Workbook

Sheet Cover
B2: SchoolHub / SIPlat — System Test Script
B3: End-to-end system testing across all portals (web) and the mobile app
B5: Document | C5: System Test Script (SIT/UAT)
B6: Product | C6: SchoolHub / SIPlat — multi-tenant schools platform
B7: Version | C7: 1.0
B8: Prepared | C8: 2026-08-15
B9: Author | C9: QA / Delivery
B10: Environment | C10: ____________________ (URL / build / device)
B11: Test data set | C11: ____________________
B12: Scope | C12: Auth & RBAC, Super-Admin, Commercial & Activation, Account-Manager scoping, School-Admin, Teacher, Parent, Driver (web + mobile), Transport-Manager, Messaging, Download Governance, Notifications, Onboarding, Security/PII, Integrations, Support, and cross-cutting regression.
B13: Out of scope | C13: Load/soak, penetration testing, and third-party provider internals (covered by separate specialist test plans).
B15: How to use this workbook
C16: 1. Test Case Index — one row per case. Fill Status, Tester, Date and Comments as you execute.
C17: 2. Detailed Steps — numbered steps for every case with Action, Test Data and Expected Result; record Actual + per-step Status.
C18: 3. Traceability — maps each case to a requirement/feature reference.
C19: 4. Summary — live pass/fail roll-up by module (updates from the Index Status column).
C20: Status values: Pass · Fail · Blocked · In Progress · Not Run. Raise a defect ID in Comments for any Fail.
B22: Legend
B23: High priority
B24: Medium priority
B25: Low priority

Sheet Summary
B2: Execution Summary
B4: Module | C4: Total | D4: Pass | E4: Fail | F4: Blocked | G4: In Progress | H4: Not Run
B5: Authentication & Session | C5: =COUNTIF('Test Case Index'!$B$2:$B$105,$B5) -> 10 | D5: =COUNTIFS('Test Case Index'!$B$2:$B$105,$B5,'Test Case Index'!$L$2:$L$105,"Pass") -> 0 | E5: =COUNTIFS('Test Case Index'!$B$2:$B$105,$B5,'Test Case Index'!$L$2:$L$105,"Fail") -> 0 | F5: =COUNTIFS('Test Case Index'!$B$2:$B$105,$B5,'Test Case Index'!$L$2:$L$105,"Blocked") -> 0 | G5: =COUNTIFS('Test Case Index'!$B$2:$B$105,$B5,'Test Case Index'!$L$2:$L$105,"In Progress") -> 0 | H5: =COUNTIFS('Test Case Index'!$B$2:$B$105,$B5,'Test Case Index'!$L$2:$L$105,"Not Run") -> 10
B6: Roles, Permissions & Isolation | C6: =COUNTIF('Test Case Index'!$B$2:$B$105,$B6) -> 6 | D6: =COUNTIFS('Test Case Index'!$B$2:$B$105,$B6,'Test Case Index'!$L$2:$L$105,"Pass") -> 0 | E6: =COUNTIFS('Test Case Index'!$B$2:$B$105,$B6,'Test Case Index'!$L$2:$L$105,"Fail") -> 0 | F6: =COUNTIFS('Test Case Index'!$B$2:$B$105,$B6,'Test Case Index'!$L$2:$L$105,"Blocked") -> 0 | G6: =COUNTIFS('Test Case Index'!$B$2:$B$105,$B6,'Test Case Index'!$L$2:$L$105,"In Progress") -> 0 | H6: =COUNTIFS('Test Case Index'!$B$2:$B$105,$B6,'Test Case Index'!$L$2:$L$105,"Not Run") -> 6
B7: Account Manager Scoping | C7: =COUNTIF('Test Case Index'!$B$2:$B$105,$B7) -> 4 | D7: =COUNTIFS('Test Case Index'!$B$2:$B$105,$B7,'Test Case Index'!$L$2:$L$105,"Pass") -> 0 | E7: =COUNTIFS('Test Case Index'!$B$2:$B$105,$B7,'Test Case Index'!$L$2:$L$105,"Fail") -> 0 | F7: =COUNTIFS('Test Case Index'!$B$2:$B$105,$B7,'Test Case Index'!$L$2:$L$105,"Blocked") -> 0 | G7: =COUNTIFS('Test Case Index'!$B$2:$B$105,$B7,'Test Case Index'!$L$2:$L$105,"In Progress") -> 0 | H7: =COUNTIFS('Test Case Index'!$B$2:$B$105,$B7,'Test Case Index'!$L$2:$L$105,"Not Run") -> 4
B8: Super-Admin / Platform Mgmt | C8: =COUNTIF('Test Case Index'!$B$2:$B$105,$B8) -> 5 | D8: =COUNTIFS('Test Case Index'!$B$2:$B$105,$B8,'Test Case Index'!$L$2:$L$105,"Pass") -> 0 | E8: =COUNTIFS('Test Case Index'!$B$2:$B$105,$B8,'Test Case Index'!$L$2:$L$105,"Fail") -> 0 | F8: =COUNTIFS('Test Case Index'!$B$2:$B$105,$B8,'Test Case Index'!$L$2:$L$105,"Blocked") -> 0 | G8: =COUNTIFS('Test Case Index'!$B$2:$B$105,$B8,'Test Case Index'!$L$2:$L$105,"In Progress") -> 0 | H8: =COUNTIFS('Test Case Index'!$B$2:$B$105,$B8,'Test Case Index'!$L$2:$L$105,"Not Run") -> 5
B9: Commercial & Purchase Orders | C9: =COUNTIF('Test Case Index'!$B$2:$B$105,$B9) -> 6 | D9: =COUNTIFS('Test Case Index'!$B$2:$B$105,$B9,'Test Case Index'!$L$2:$L$105,"Pass") -> 0 | E9: =COUNTIFS('Test Case Index'!$B$2:$B$105,$B9,'Test Case Index'!$L$2:$L$105,"Fail") -> 0 | F9: =COUNTIFS('Test Case Index'!$B$2:$B$105,$B9,'Test Case Index'!$L$2:$L$105,"Blocked") -> 0 | G9: =COUNTIFS('Test Case Index'!$B$2:$B$105,$B9,'Test Case Index'!$L$2:$L$105,"In Progress") -> 0 | H9: =COUNTIFS('Test Case Index'!$B$2:$B$105,$B9,'Test Case Index'!$L$2:$L$105,"Not Run") -> 6
B10: Invoice & Activation Workflow | C10: =COUNTIF('Test Case Index'!$B$2:$B$105,$B10) -> 7 | D10: =COUNTIFS('Test Case Index'!$B$2:$B$105,$B10,'Test Case Index'!$L$2:$L$105,"Pass") -> 0 | E10: =COUNTIFS('Test Case Index'!$B$2:$B$105,$B10,'Test Case Index'!$L$2:$L$105,"Fail") -> 0 | F10: =COUNTIFS('Test Case Index'!$B$2:$B$105,$B10,'Test Case Index'!$L$2:$L$105,"Blocked") -> 0 | G10: =COUNTIFS('Test Case Index'!$B$2:$B$105,$B10,'Test Case Index'!$L$2:$L$105,"In Progress") -> 0 | H10: =COUNTIFS('Test Case Index'!$B$2:$B$105,$B10,'Test Case Index'!$L$2:$L$105,"Not Run") -> 7
B11: Messaging | C11: =COUNTIF('Test Case Index'!$B$2:$B$105,$B11) -> 10 | D11: =COUNTIFS('Test Case Index'!$B$2:$B$105,$B11,'Test Case Index'!$L$2:$L$105,"Pass") -> 0 | E11: =COUNTIFS('Test Case Index'!$B$2:$B$105,$B11,'Test Case Index'!$L$2:$L$105,"Fail") -> 0 | F11: =COUNTIFS('Test Case Index'!$B$2:$B$105,$B11,'Test Case Index'!$L$2:$L$105,"Blocked") -> 0 | G11: =COUNTIFS('Test Case Index'!$B$2:$B$105,$B11,'Test Case Index'!$L$2:$L$105,"In Progress") -> 0 | H11: =COUNTIFS('Test Case Index'!$B$2:$B$105,$B11,'Test Case Index'!$L$2:$L$105,"Not Run") -> 10
B12: Download Governance | C12: =COUNTIF('Test Case Index'!$B$2:$B$105,$B12) -> 5 | D12: =COUNTIFS('Test Case Index'!$B$2:$B$105,$B12,'Test Case Index'!$L$2:$L$105,"Pass") -> 0 | E12: =COUNTIFS('Test Case Index'!$B$2:$B$105,$B12,'Test Case Index'!$L$2:$L$105,"Fail") -> 0 | F12: =COUNTIFS('Test Case Index'!$B$2:$B$105,$B12,'Test Case Index'!$L$2:$L$105,"Blocked") -> 0 | G12: =COUNTIFS('Test Case Index'!$B$2:$B$105,$B12,'Test Case Index'!$L$2:$L$105,"In Progress") -> 0 | H12: =COUNTIFS('Test Case Index'!$B$2:$B$105,$B12,'Test Case Index'!$L$2:$L$105,"Not Run") -> 5
B13: School-Admin Portal | C13: =COUNTIF('Test Case Index'!$B$2:$B$105,$B13) -> 5 | D13: =COUNTIFS('Test Case Index'!$B$2:$B$105,$B13,'Test Case Index'!$L$2:$L$105,"Pass") -> 0 | E13: =COUNTIFS('Test Case Index'!$B$2:$B$105,$B13,'Test Case Index'!$L$2:$L$105,"Fail") -> 0 | F13: =COUNTIFS('Test Case Index'!$B$2:$B$105,$B13,'Test Case Index'!$L$2:$L$105,"Blocked") -> 0 | G13: =COUNTIFS('Test Case Index'!$B$2:$B$105,$B13,'Test Case Index'!$L$2:$L$105,"In Progress") -> 0 | H13: =COUNTIFS('Test Case Index'!$B$2:$B$105,$B13,'Test Case Index'!$L$2:$L$105,"Not Run") -> 5
B14: Teacher Portal | C14: =COUNTIF('Test Case Index'!$B$2:$B$105,$B14) -> 4 | D14: =COUNTIFS('Test Case Index'!$B$2:$B$105,$B14,'Test Case Index'!$L$2:$L$105,"Pass") -> 0 | E14: =COUNTIFS('Test Case Index'!$B$2:$B$105,$B14,'Test Case Index'!$L$2:$L$105,"Fail") -> 0 | F14: =COUNTIFS('Test Case Index'!$B$2:$B$105,$B14,'Test Case Index'!$L$2:$L$105,"Blocked") -> 0 | G14: =COUNTIFS('Test Case Index'!$B$2:$B$105,$B14,'Test Case Index'!$L$2:$L$105,"In Progress") -> 0 | H14: =COUNTIFS('Test Case Index'!$B$2:$B$105,$B14,'Test Case Index'!$L$2:$L$105,"Not Run") -> 4
B15: Parent Portal | C15: =COUNTIF('Test Case Index'!$B$2:$B$105,$B15) -> 5 | D15: =COUNTIFS('Test Case Index'!$B$2:$B$105,$B15,'Test Case Index'!$L$2:$L$105,"Pass") -> 0 | E15: =COUNTIFS('Test Case Index'!$B$2:$B$105,$B15,'Test Case Index'!$L$2:$L$105,"Fail") -> 0 | F15: =COUNTIFS('Test Case Index'!$B$2:$B$105,$B15,'Test Case Index'!$L$2:$L$105,"Blocked") -> 0 | G15: =COUNTIFS('Test Case Index'!$B$2:$B$105,$B15,'Test Case Index'!$L$2:$L$105,"In Progress") -> 0 | H15: =COUNTIFS('Test Case Index'!$B$2:$B$105,$B15,'Test Case Index'!$L$2:$L$105,"Not Run") -> 5
B16: Driver Portal (Web) | C16: =COUNTIF('Test Case Index'!$B$2:$B$105,$B16) -> 4 | D16: =COUNTIFS('Test Case Index'!$B$2:$B$105,$B16,'Test Case Index'!$L$2:$L$105,"Pass") -> 0 | E16: =COUNTIFS('Test Case Index'!$B$2:$B$105,$B16,'Test Case Index'!$L$2:$L$105,"Fail") -> 0 | F16: =COUNTIFS('Test Case Index'!$B$2:$B$105,$B16,'Test Case Index'!$L$2:$L$105,"Blocked") -> 0 | G16: =COUNTIFS('Test Case Index'!$B$2:$B$105,$B16,'Test Case Index'!$L$2:$L$105,"In Progress") -> 0 | H16: =COUNTIFS('Test Case Index'!$B$2:$B$105,$B16,'Test Case Index'!$L$2:$L$105,"Not Run") -> 4
... B25: Cross-cutting & Regression | C25: =COUNTIF('Test Case Index'!$B$2:$B$105,$B25) -> 3 | D25: =COUNTIFS('Test Case Index'!$B$2:$B$105,$B25,'Test Case Index'!$L$2:$L$105,"Pass") -> 0 | E25: =COUNTIFS('Test Case Index'!$B$2:$B$105,$B25,'Test Case Index'!$L$2:$L$105,"Fail") -> 0 | F25: =COUNTIFS('Test Case Index'!$B$2:$B$105,$B25,'Test Case Index'!$L$2:$L$105,"Blocked") -> 0 | G25: =COUNTIFS('Test Case Index'!$B$2:$B$105,$B25,'Test Case Index'!$L$2:$L$105,"In Progress") -> 0 | H25: =COUNTIFS('Test Case Index'!$B$2:$B$105,$B25,'Test Case Index'!$L$2:$L$105,"Not Run") -> 3
B26: TOTAL | C26: =SUM(C5:C25) -> 104 | D26: =SUM(D5:D25) -> 0 | E26: =SUM(E5:E25) -> 0 | F26: =SUM(F5:F25) -> 0 | G26: =SUM(G5:G25) -> 0 | H26: =SUM(H5:H25) -> 104
B28: Pass rate (of executed) | C28: =IFERROR(D26/(D26+E26+F26),0) -> 0
B29: Executed | C29: =D26+E26+F26 -> 0
B30: Coverage (cases) | C30: =C26 -> 104

Sheet Test Case Index
A1: Case ID | B1: Module | C1: Sub-Area | D1: Title | E1: Priority | F1: Type | G1: Role / Actor | H1: Platform | I1: Preconditions | J1: Expected Result | K1: Req Ref | L1: Status | M1: Tester | N1: Date | O1: Comments
A2: TC-AUTH-001 | B2: Authentication & Session | C2: Login | D2: Valid sign-in with correct credentials | E2: High | F2: Functional | G2: Any registered user | H2: Both | I2: User account exists and is active; tenant is activated. | J2: User is authenticated and lands on their role home screen. | K2: REQ-SEC-Login | L2: Not Run
A3: TC-AUTH-002 | B3: Authentication & Session | C3: Login | D3: Reject invalid password | E3: High | F3: Negative | G3: Any user | H3: Both | I3: Account exists. | J3: Sign-in is refused with a generic error; no token issued. | K3: REQ-SEC-Login | L3: Not Run
A4: TC-AUTH-003 | B4: Authentication & Session | C4: Lockout | D4: Account protection after repeated failures | E4: Medium | F4: Security | G4: Any user | H4: Web | I4: Account exists; lockout policy configured. | J4: Account is temporarily locked / throttled after the configured number of failures. | K4: REQ-SEC-Policy | L4: Not Run
A5: TC-AUTH-004 | B5: Authentication & Session | C5: MFA | D5: Mandatory MFA enrolment | E5: High | F5: Functional | G5: User where policy requires MFA | H5: Both | I5: Security policy mfaRequired = true; user has no MFA yet. | J5: User is forced to enrol MFA before reaching the app. | K5: REQ-SEC-MFA | L5: Not Run
A6: TC-AUTH-005 | B6: Authentication & Session | C6: MFA | D6: MFA challenge on login | E6: High | F6: Functional | G6: MFA-enrolled user | H6: Both | I6: User already enrolled in MFA. | J6: Login requires a valid TOTP; wrong codes rejected. | K6: REQ-SEC-MFA | L6: Not Run
A7: TC-AUTH-006 | B7: Authentication & Session | C7: Password | D7: Forced password change on expiry | E7: Medium | F7: Functional | G7: User with expired password | H7: Both | I7: passwordChangedAt older than policy max age. | J7: User must set a new password before continuing. | K7: REQ-SEC-Policy | L7: Not Run
A8: TC-AUTH-007 | B8: Authentication & Session | C8: Session | D8: Remember-me persists session | E8: Low | F8: Functional | G8: Any user | H8: Mobile | I8: User signs in with remember = true. | J8: Session restored on next app open without re-login. | K8: REQ-SEC-Login | L8: Not Run
A9: TC-AUTH-008 | B9: Authentication & Session | C9: Session | D9: Logout invalidates session | E9: High | F9: Security | G9: Any user | H9: Both | I9: User is signed in. | J9: Session ends and protected routes are inaccessible. | K9: REQ-SEC-Login | L9: Not Run
A10: TC-AUTH-009 | B10: Authentication & Session | C10: Biometric | D10: Biometric unlock on mobile | E10: Low | F10: Functional | G10: Mobile user with biometrics | H10: Mobile | I10: Device has enrolled biometrics; prior remembered session. | J10: Biometric success restores the session. | K10: REQ-Mobile-Biometric | L10: Not Run
A11: TC-AUTH-010 | B11: Authentication & Session | C11: Password | D11: Self-service password reset | E11: Medium | F11: Functional | G11: Any user | H11: Web | I11: Account exists with a valid email. | J11: Reset link path works and old password no longer authenticates. | K11: REQ-SEC-Login | L11: Not Run
A12: TC-RBAC-001 | B12: Roles, Permissions & Isolation | C12: Menu | D12: Role-appropriate navigation | E12: High | F12: RBAC | G12: School Administrator | H12: Web | I12: User holds SchoolAdministrator role. | J12: Only permitted sections are visible. | K12: REQ-RBAC-Menu | L12: Not Run
A13: TC-RBAC-002 | B13: Roles, Permissions & Isolation | C13: Enforcement | D13: Deny unauthorized route access | E13: High | F13: Security | G13: Low-privilege user | H13: Both | I13: User lacks the target permission. | J13: Direct navigation to a protected route is blocked. | K13: REQ-RBAC-Enforce | L13: Not Run
... A105: TC-REG-003 | B105: Cross-cutting & Regression | C105: Perf | D105: Key screens load within budget | E105: Low | F105: Non-functional | G105: Any user | H105: Both | I105: Representative data volume. | J105: Primary dashboards load within an acceptable time. | K105: REQ-Perf | L105: Not Run

Sheet Detailed Steps
A1: Case ID | B1: Module | C1: Case Title | D1: Step | E1: Action | F1: Test Data | G1: Expected Result | H1: Actual Result | I1: Status | J1: Comments
A2: TC-AUTH-001 | B2: Authentication & Session | C2: Valid sign-in with correct credentials | D2: 1 | E2: Navigate to the sign-in page | F2: - | G2: Login form is displayed with email & password fields. | I2: Not Run
D3: 2 | E3: Enter valid email and password | F3: valid credentials | G3: Fields accept input; password is masked. | I3: Not Run
D4: 3 | E4: Tap Sign in | F4: - | G4: Session token issued; user routed to their role dashboard. | I4: Not Run
A5: TC-AUTH-002 | B5: Authentication & Session | C5: Reject invalid password | D5: 1 | E5: Enter a valid email with a wrong password | F5: wrong password | G5: Input accepted. | I5: Not Run
D6: 2 | E6: Tap Sign in | F6: - | G6: Error 'Sign-in failed' shown; user stays on login; no session created. | I6: Not Run
A7: TC-AUTH-003 | B7: Authentication & Session | C7: Account protection after repeated failures | D7: 1 | E7: Submit wrong password up to the configured threshold | F7: wrong password x N | G7: Each attempt is rejected. | I7: Not Run
D8: 2 | E8: Submit one more attempt | F8: wrong password | G8: Further attempts are throttled/locked per policy and audited. | I8: Not Run
A9: TC-AUTH-004 | B9: Authentication & Session | C9: Mandatory MFA enrolment | D9: 1 | E9: Sign in with valid credentials | F9: valid credentials | G9: mfaEnrollmentRequired gate triggers; enrolment screen with secret/QR shown. | I9: Not Run
D10: 2 | E10: Scan secret in an authenticator and enter the 6-digit code | F10: current TOTP | G10: Code accepted; enrolment stored. | I10: Not Run
D11: 3 | E11: Continue | F11: - | G11: User proceeds to dashboard; subsequent logins require MFA. | I11: Not Run
A12: TC-AUTH-005 | B12: Authentication & Session | C12: MFA challenge on login | D12: 1 | E12: Sign in with valid credentials | F12: valid credentials | G12: mfaRequired response; code prompt shown. | I12: Not Run
D13: 2 | E13: Enter an incorrect code | F13: 000000 | G13: Rejected with error; no session. | I13: Not Run
D14: 3 | E14: Enter the correct code | F14: current TOTP | G14: Session issued; dashboard shown. | I14: Not Run
A15: TC-AUTH-006 | B15: Authentication & Session | C15: Forced password change on expiry | D15: 1 | E15: Sign in | F15: valid credentials | G15: passwordExpired gate triggers; change-password screen shown. | I15: Not Run
D16: 2 | E16: Submit a compliant new password | F16: new password | G16: Password updated; session rotated; user re-authenticated. | I16: Not Run
A17: TC-AUTH-007 | B17: Authentication & Session | C17: Remember-me persists session | D17: 1 | E17: Sign in with remember enabled | F17: valid credentials | G17: Token stored securely; remember flag = 1. | I17: Not Run
D18: 2 | E18: Close and reopen the app | F18: - | G18: Bootstrap runs with stored token; user lands on dashboard without re-entering credentials. | I18: Not Run
A19: TC-AUTH-008 | B19: Authentication & Session | C19: Logout invalidates session | D19: 1 | E19: Tap Logout | F19: - | G19: Token cleared; remember flag removed; returned to login. | I19: Not Run
D20: 2 | E20: Attempt to reopen a protected screen / API | F20: - | G20: Access denied / redirected to login. | I20: Not Run
A21: TC-AUTH-009 | B21: Authentication & Session | C21: Biometric unlock on mobile | D21: 1 | E21: Open app with a stored session | F21: - | G21: Biometric prompt shown. | I21: Not Run
D22: 2 | E22: Authenticate with Face/Touch ID | F22: valid biometric | G22: Bootstrap loads; dashboard shown. | I22: Not Run
D23: 3 | E23: Fail/cancel biometric | F23: cancel | G23: Session not restored; user remains on lock/login. | I23: Not Run
A24: TC-AUTH-010 | B24: Authentication & Session | C24: Self-service password reset | D24: 1 | E24: Use 'Forgot password' and submit the account email | F24: registered email | G24: Reset initiation confirmed (no account enumeration). | I24: Not Run
D25: 2 | E25: Complete reset with a new password | F25: new password | G25: New password set. | I25: Not Run
D26: 3 | E26: Sign in with the old password | F26: old password | G26: Rejected. | I26: Not Run
A27: TC-RBAC-001 | B27: Roles, Permissions & Isolation | C27: Role-appropriate navigation | D27: 1 | E27: Sign in as a School Administrator | F27: - | G27: Dashboard loads. | I27: Not Run
D28: 2 | E28: Review the left navigation | F28: - | G28: Admin sections present; platform-only items absent. | I28: Not Run
A29: TC-RBAC-002 | B29: Roles, Permissions & Isolation | C29: Deny unauthorized route access | D29: 1 | E29: Sign in as a user without a given permission | F29: - | G29: Dashboard loads. | I29: Not Run
D30: 2 | E30: Manually navigate to a protected URL/endpoint | F30: protected route | G30: 403 / access-denied; no data leaked. | I30: Not Run
A31: TC-RBAC-003 | B31: Roles, Permissions & Isolation | C31: Tenant role override grants access | D31: 1 | E31: Assign an override permission to a role | F31: permission grant | G31: Saved. | I31: Not Run
D32: 2 | E32: Sign in as a user with that role | F32: - | G32: The newly permitted section is now accessible. | I32: Not Run
A33: TC-RBAC-004 | B33: Roles, Permissions & Isolation | C33: Platform-admin plane access | D33: 1 | E33: Sign in as a platform admin | F33: - | G33: Platform areas visible per staffAreas/canAccessArea. | I33: Not Run
D34: 2 | E34: Sign in as a normal tenant admin | F34: - | G34: Platform plane is not reachable. | I34: Not Run
A35: TC-RBAC-005 | B35: Roles, Permissions & Isolation | C35: Cross-tenant access is blocked | D35: 1 | E35: Sign in as an admin of Tenant A | F35: - | G35: Only Tenant A data listed. | I35: Not Run
D36: 2 | E36: Request a Tenant B record id directly | F36: B record id | G36: Access denied via assertTenantAccess; nothing returned. | I36: Not Run
A37: TC-RBAC-006 | B37: Roles, Permissions & Isolation | C37: Staff-area gate enforced | D37: 1 | E37: Access the staff area as an authorised staff member | F37: - | G37: Allowed. | I37: Not Run
D38: 2 | E38: Access it as a non-staff user | F38: - | G38: Blocked. | I38: Not Run
A39: TC-AM-001 | B39: Account Manager Scoping | C39: AM sees only in-scope schools (geo) | D39: 1 | E39: Sign in as an Account Manager | F39: - | G39: Portfolio dashboard loads. | I39: Not Run
D40: 2 | E40: Open the schools list | F40: - | G40: Only schools within the AM's county/country appear. | I40: Not Run
...

Sheet Traceability
A1: Case ID | B1: Module | C1: Title | D1: Requirement / Feature Ref | E1: Priority
A2: TC-AUTH-001 | B2: Authentication & Session | C2: Valid sign-in with correct credentials | D2: REQ-SEC-Login | E2: High
A3: TC-AUTH-002 | B3: Authentication & Session | C3: Reject invalid password | D3: REQ-SEC-Login | E3: High
A4: TC-AUTH-003 | B4: Authentication & Session | C4: Account protection after repeated failures | D4: REQ-SEC-Policy | E4: Medium
A5: TC-AUTH-004 | B5: Authentication & Session | C5: Mandatory MFA enrolment | D5: REQ-SEC-MFA | E5: High
A6: TC-AUTH-005 | B6: Authentication & Session | C6: MFA challenge on login | D6: REQ-SEC-MFA | E6: High
A7: TC-AUTH-006 | B7: Authentication & Session | C7: Forced password change on expiry | D7: REQ-SEC-Policy | E7: Medium
A8: TC-AUTH-007 | B8: Authentication & Session | C8: Remember-me persists session | D8: REQ-SEC-Login | E8: Low
A9: TC-AUTH-008 | B9: Authentication & Session | C9: Logout invalidates session | D9: REQ-SEC-Login | E9: High
A10: TC-AUTH-009 | B10: Authentication & Session | C10: Biometric unlock on mobile | D10: REQ-Mobile-Biometric | E10: Low
A11: TC-AUTH-010 | B11: Authentication & Session | C11: Self-service password reset | D11: REQ-SEC-Login | E11: Medium
A12: TC-RBAC-001 | B12: Roles, Permissions & Isolation | C12: Role-appropriate navigation | D12: REQ-RBAC-Menu | E12: High
... A105: TC-REG-003 | B105: Cross-cutting & Regression | C105: Key screens load within budget | D105: REQ-Perf | E105: Low
